<?xml version="1.0"?>
<robot name="mower_robot" xmlns:xacro="http://www.ros.org/wiki/xacro">
  <link name="base_link">
    <inertial>
      <mass value="2.0"/>
      <inertia ixx="0.05" ixy="0.0" ixz="0.0" iyy="0.05" iyz="0.0" izz="0.05"/>
    </inertial>
    <visual>
      <geometry>
        <box size="0.4 0.3 0.1"/>
      </geometry>
      <material name="blue">
        <color rgba="0 0 1 1"/>
      </material>
    </visual>
    <collision>
      <geometry>
        <box size="0.4 0.3 0.1"/>
      </geometry>
    </collision>
  </link>

  <!-- Rear Left Wheel -->
  <link name="left_rear_wheel">
    <inertial>
      <mass value="0.2"/>
      <inertia ixx="0.001" ixy="0.0" ixz="0.0" iyy="0.001" iyz="0.0" izz="0.001"/>
    </inertial>
    <visual>
      <geometry>
        <cylinder radius="0.1" length="0.05"/>
      </geometry>
      <material name="black">
        <color rgba="0 0 0 1"/>
      </material>
    </visual>
    <collision>
      <geometry>
        <cylinder radius="0.1" length="0.05"/>
      </geometry>
    </collision>
  </link>

  <!-- Rear Right Wheel -->
  <link name="right_rear_wheel">
    <inertial>
      <mass value="0.2"/>
      <inertia ixx="0.001" ixy="0.0" ixz="0.0" iyy="0.001" iyz="0.0" izz="0.001"/>
    </inertial>
    <visual>
      <geometry>
        <cylinder radius="0.1" length="0.05"/>
      </geometry>
      <material name="black"/>
    </visual>
    <collision>
      <geometry>
        <cylinder radius="0.1" length="0.05"/>
      </geometry>
    </collision>
  </link>

  <!-- Front Left Caster -->
  <link name="left_front_caster">
    <inertial>
      <mass value="0.1"/>
      <inertia ixx="0.0005" ixy="0.0" ixz="0.0" iyy="0.0005" iyz="0.0" izz="0.0005"/>
    </inertial>
    <visual>
      <geometry>
        <cylinder radius="0.1" length="0.05"/>
      </geometry>
      <material name="grey">
        <color rgba="0.5 0.5 0.5 1"/>
      </material>
    </visual>
    <collision>
      <geometry>
        <cylinder radius="0.1" length="0.05"/>
      </geometry>
    </collision>
  </link>

  <!-- Front Right Caster -->
  <link name="right_front_caster">
    <inertial>
      <mass value="0.1"/>
      <inertia ixx="0.0005" ixy="0.0" ixz="0.0" iyy="0.0005" iyz="0.0" izz="0.0005"/>
    </inertial>
    <visual>
      <geometry>
        <cylinder radius="0.1" length="0.05"/>
      </geometry>
      <material name="grey"/>
    </visual>
    <collision>
      <geometry>
        <cylinder radius="0.1" length="0.05"/>
      </geometry>
    </collision>
  </link>

  <!-- Joints -->
  <joint name="base_to_left_rear_wheel" type="continuous">
    <parent link="base_link"/>
    <child link="left_rear_wheel"/>
    <origin xyz="0.15 0.15 -0.05" rpy="1.5708 0 0"/>
    <axis xyz="0 0 1"/>
  </joint>
  <joint name="base_to_right_rear_wheel" type="continuous">
    <parent link="base_link"/>
    <child link="right_rear_wheel"/>
    <origin xyz="0.15 -0.15 -0.05" rpy="1.5708 0 0"/>
    <axis xyz="0 0 1"/>
  </joint>
  <joint name="base_to_left_front_caster" type="fixed">
    <parent link="base_link"/>
    <child link="left_front_caster"/>
    <origin xyz="-0.15 0.15 -0.05" rpy="1.5708 0 0"/>
  </joint>
  <joint name="base_to_right_front_caster" type="fixed">
    <parent link="base_link"/>
    <child link="right_front_caster"/>
    <origin xyz="-0.15 -0.15 -0.05" rpy="1.5708 0 0"/>
  </joint>

  <!-- LIDAR -->
  <link name="lidar_link">
    <inertial>
      <mass value="0.1"/>
      <inertia ixx="0.0001" ixy="0.0" ixz="0.0" iyy="0.0001" iyz="0.0" izz="0.0001"/>
    </inertial>
    <visual>
      <geometry>
        <cylinder radius="0.05" length="0.05"/>
      </geometry>
      <material name="red">
        <color rgba="1 0 0 1"/>
      </material>
    </visual>
    <collision>
      <geometry>
        <cylinder radius="0.05" length="0.05"/>
      </geometry>
    </collision>
    <sensor name="lidar" type="ray">
      <pose>0 0 0 0 0 0</pose>
      <ray>
        <scan>
          <horizontal>
            <samples>360</samples>
            <resolution>1</resolution>
            <min_angle>-3.14159</min_angle>
            <max_angle>3.14159</max_angle>
          </horizontal>
        </scan>
        <range>
          <min>0.1</min>
          <max>10.0</max>
          <resolution>0.01</resolution>
        </range>
      </ray>
      <plugin name="lidar_plugin" filename="libgazebo_ros_laser.so">
        <ros>
          <namespace>/mower_robot</namespace>
          <remapping>scan:=scan</remapping>
        </ros>
        <frame_name>lidar_link</frame_name>
      </plugin>
    </sensor>
  </link>
  <joint name="base_to_lidar" type="fixed">
    <parent link="base_link"/>
    <child link="lidar_link"/>
    <origin xyz="0 0 0.1" rpy="0 0 0"/>
  </joint>

  <!-- Differential Drive Plugin -->
  <gazebo>
    <plugin name="diff_drive" filename="libgazebo_ros_diff_drive.so">
      <ros>
        <namespace>/mower_robot</namespace>
      </ros>
      <left_joint>base_to_left_rear_wheel</left_joint>
      <right_joint>base_to_right_rear_wheel</right_joint>
      <wheel_separation>0.3</wheel_separation>
      <wheel_diameter>0.2</wheel_diameter>
      <max_wheel_torque>50</max_wheel_torque>
      <max_wheel_acceleration>20</max_wheel_acceleration>
      <odometry_frame>odom</odometry_frame>
      <robot_base_frame>base_link</robot_base_frame>
      <publish_odom>true</publish_odom>
      <publish_odom_tf>true</publish_odom_tf>
    </plugin>
  </gazebo>

  <!-- Caster Wheel Friction -->
  <gazebo reference="left_front_caster">
    <mu1>0.1</mu1>
    <mu2>0.1</mu2>
    <material>Gazebo/Grey</material>
  </gazebo>
  <gazebo reference="right_front_caster">
    <mu1>0.1</mu1>
    <mu2>0.1</mu2>
    <material>Gazebo/Grey</material>
  </gazebo>
</robot>